Workbook
Name Hours: Rates!$B$5
Name FargateCpuRate: Rates!$B$6
Name FargateMemRate: Rates!$B$7
Name AlbHourly: Rates!$B$8
Name LcuHourly: Rates!$B$9
Name Ipv4Hourly: Rates!$B$10
Name Gp3Rate: Rates!$B$11
Name SecretMonthly: Rates!$B$12
Name SecretApiRate: Rates!$B$13
Name CwIngest: Rates!$B$14
Name CwStore: Rates!$B$15
Name CwFreeGb: Rates!$B$16
Name XferRate: Rates!$B$17
Name XferFreeGb: Rates!$B$18
Name NatHourly: Rates!$B$19
Name NatPerGb: Rates!$B$20
Name AuroraAcu: Rates!$B$21
Name AuroraGb: Rates!$B$22
Name CpuTarget: Rates!$B$23
Name ExpressMax: Rates!$B$24
Name TaskQuota: Rates!$B$25
Name FargateMaxVcpu: Rates!$B$26
Name FargateVcpuQuota: Rates!$B$27
Name AlbIpv4: Rates!$B$28
Name MinLcu: Rates!$B$29
Name SecretCount: Rates!$B$30
Name SecretCalls: Rates!$B$31
Name ConnDivisor: Rates!$B$32
Name ConnCapMax: Rates!$B$33
Name AcuPerVcpu: Rates!$B$34
Name Users: Inputs!$B$5
Name Bots: Inputs!$B$6
Name Offers: Inputs!$B$7
Name Messages: Inputs!$B$8
Name ReqPerUser: Inputs!$B$9
Name ReqPerBot: Inputs!$B$10
Name ReqPerOffer: Inputs!$B$11
Name ReqPerMessage: Inputs!$B$12
Name Peak: Inputs!$B$13
Name ReqKB: Inputs!$B$14
Name RespMult: Inputs!$B$15
Name ReqPerConn: Inputs!$B$16
Name LogPerM: Inputs!$B$17
Name DbFloor: Inputs!$B$18
Name DbPerM: Inputs!$B$19
Name AppVcpuS: Inputs!$B$20
Name DbVcpuS: Inputs!$B$21
Name HoldS: Inputs!$B$22
Name NatOn: Inputs!$B$23
Name TaskPublicIp: Inputs!$B$24
Name ClassNames: Classes!$A$5:$A$265
Name ClassPrices: Classes!$B$5:$B$265
Name ClassVcpu: Classes!$C$5:$C$265
Name ClassMem: Classes!$D$5:$D$265
Name ClassCap: Classes!$F$5:$F$265
Name ClassUse: Classes!$G$5:$G$265

Sheet Inputs
A1: FIN-2026-10-02-02 inputs
A2: Yellow cells are for the CEO. The four daily volumes are valid from 1,000 to 10,000,000. Anything else on this sheet is a finance assumption, not a product requirement. Defaults put all four volumes at 1,000 and the per-exchange and per-actor multipliers at 1, so one 0.25 vCPU task and db.t4g.micro still clear the 60% target. This is an estimate. No AWS account, no provision, no spend. PoC stays at $0.
A4: Input | B4: Value | C4: Unit | D4: Kind | E4: Why this default
A5: Daily users | B5: 1000 | C5: count per day | D5: CEO volume | E5: Brief default. Valid 1,000 to 10,000,000.
A6: Daily bots | B6: 1000 | C6: count per day | D6: CEO volume | E6: Brief default. Valid 1,000 to 10,000,000.
A7: Daily offer exchanges | B7: 1000 | C7: count per day | D7: CEO volume | E7: Brief default. Valid 1,000 to 10,000,000.
A8: Daily message exchanges | B8: 1000 | C8: count per day | D8: CEO volume | E8: Brief default. Valid 1,000 to 10,000,000.
A9: Requests per user-day | B9: 1 | C9: requests | D9: Finance assumption | E9: No product request rate was stated. Default 1 keeps the floor on one small task.
A10: Requests per bot-day | B10: 1 | C10: requests | D10: Finance assumption | E10: Same. Not a product requirement.
A11: Requests per offer | B11: 1 | C11: requests | D11: Finance assumption | E11: Brief: per-exchange multiplier defaults to 1.
A12: Requests per message | B12: 1 | C12: requests | D12: Finance assumption | E12: Brief: per-exchange multiplier defaults to 1.
A13: Peak to average | B13: 1 | C13: ratio | D13: Finance assumption | E13: 1 means the rung is the average hour, not a spike. Raise it to size for a peak.
A14: Average request KB | B14: 1 | C14: KB | D14: Finance assumption | E14: Used for LCU processed bytes and data-transfer GB. Not a measured payload.
A15: Response KB per request KB | B15: 1 | C15: ratio | D15: Finance assumption | E15: Response size = request KB times this. Default 1.
A16: Requests per new connection | B16: 1 | C16: requests | D16: Finance assumption | E16: Default 1 assumes no keep-alive, so new connections equal peak requests. Raise it if connections are reused.
... A24: Task public IPv4 | B24: 0 | C24: 0 off, 1 on | D24: Finance assumption | E24: Defaults off so the floor keeps FIN-2026-10-02-01's two load-balancer addresses. Express Mode turns assignPublicIp on for the default public subnets, which would be one address per task. Turn this on to see that.
A26: Range check
A27: Four daily volumes | B27: =IF(OR(Users<1000,Users>10000000,Bots<1000,Bots>10000000,Offers<1000,Offers>10000000,Messages<1000,Messages>10000000),"Outside 1,000 to 10,000,000","In range") | C27: Flags a typed volume outside the brief. The rungs themselves stay inside the range.
A29: What stays $0 unless you turn NAT on
A30: Multi-AZ | B30: 0 | C30: A later scale step, not the single-AZ base.
A31: Read replicas | B31: 0 | C31: Same. Not added as a second database.
A32: NAT gateway | B32: 0 | C32: Stays $0 while NAT on is 0. The Live sheet prices one gateway when you set it to 1.
A33: S3 | B33: 0 | C33: No artifact bucket in this step.
A34: Cognito | B34: 0 | C34: Not a Step 2 deliverable.
A35: Customer-managed KMS vault | B35: 0 | C35: Later maturity. Default encryption is not priced as a vault.
A36: Paid APM and X-Ray | B36: 0 | C36: Excluded. CloudWatch default metrics stay inside the free tier until log GB exceeds 5.

Sheet Live
A1: Live case
A2: This case follows the yellow cells on Inputs. Change those cells and this sheet moves. Every dollar is a formula. Aurora is an alternate column and is not in the total. Multi-AZ, replicas, S3, Cognito, KMS vault, and paid APM stay at $0. NAT is $0 until Inputs NAT on = 1.
A4: Resource or line | B4: Value | C4: Unit or note
A5: Daily requests | B5: =(Users*ReqPerUser+Bots*ReqPerBot+Offers*ReqPerOffer+Messages*ReqPerMessage) | C5: Sum of the four volumes times their multipliers.
A6: Monthly requests | B6: =B5*Hours/24 | C6: Daily requests times 730/24, so the month matches the 730-hour rates.
A7: Average requests per second | B7: =B5/86400 | C7: Daily requests divided by 86,400.
A8: Peak requests per second | B8: =B7*Peak | C8: Average times the peak-to-average finance assumption.
A9: App vCPU required at the 60% target | B9: =B8*AppVcpuS/CpuTarget | C9: Peak requests per second times vCPU-seconds per request, divided by 0.60.
A10: DB vCPU required at the 60% target | B10: =B8*DbVcpuS/CpuTarget | C10: Same shape, using the database vCPU-seconds assumption.
A11: Task vCPU | B11: =IF(MAX(1,ROUNDUP(B9/0.25,0))<=TaskQuota,0.25,IF(MAX(1,ROUNDUP(B9/0.5,0))<=TaskQuota,0.5,IF(MAX(1,ROUNDUP(B9/1,0))<=TaskQuota,1,IF(MAX(1,ROUNDUP(B9/2,0))<=TaskQuota,2,IF(MAX(1,ROUNDUP(B9/4,0))<=TaskQuota,4,IF(MAX(1,ROUNDUP(B9/8,0))<=TaskQuota,8,IF(MAX(1,ROUNDUP(B9/16,0))<=TaskQuota,16,32))))))) | C11: Smallest Fargate vCPU whose task count stays within the 5,000 tasks-per-service quota. 0.25 until that quota binds. 32 vCPU is the maximum task size.
A12: Tasks | B12: =MAX(1,ROUNDUP(B9/B11,0)) | C12: At least one task, which is the Express minimum.
A13: Memory GB per task | B13: =IF(B11=0.25,0.5,IF(B11=0.5,1,IF(B11=1,2,IF(B11=2,4,IF(B11=4,8,IF(B11=8,16,IF(B11=16,32,60))))))) | C13: Linux minimum memory for that vCPU. 0.25 vCPU uses 0.5 GB, which is the 512 MiB minimum.
A14: Total vCPU | B14: =B12*B11 | C14: Tasks times vCPU per task.
A15: Total memory GB | B15: =B12*B13 | C15: Tasks times memory per task.
A16: New-connection LCU | B16: =B8/ReqPerConn/25 | C16: Peak requests per second, divided by requests per connection, divided by 25.
A17: Active-connection LCU | B17: =(B8/ReqPerConn)*HoldS/3000 | C17: Concurrent connections divided by 3,000.
A18: Processed-bytes LCU | B18: =B8*3600*ReqKB*(1+RespMult)/1024/1024 | C18: GB per hour. One LCU is 1 GB per hour for container targets.
A19: ALB LCU billed | B19: =MAX(MinLcu,B16,B17,B18) | C19: The largest dimension, and at least the FIN-2026-10-02-01 floor of 1 LCU.
A20: Public IPv4 | B20: =AlbIpv4+IF(OR(NatOn=1,TaskPublicIp=0),0,B12) | C20: Two on the load balancer. Plus one per task only if task public IPv4 is on and NAT is off.
A21: Connections | B21: =MAX(1,(B8/ReqPerConn)*HoldS) | C21: Peak new connections times hold seconds. At least 1.
A22: RDS class | B22: {=IFERROR(INDEX(ClassNames,MATCH(1,(ClassUse>=B10)*(ClassCap>=B21),0)),"NO SINGLE-AZ CLASS")} | C22: Cheapest current-generation Single-AZ PostgreSQL class whose usable vCPU and connection cap both clear the assumption.
A23: RDS USD per hour | B23: {=IFERROR(INDEX(ClassPrices,MATCH(1,(ClassUse>=B10)*(ClassCap>=B21),0)),INDEX(ClassPrices,MATCH(MAX(ClassVcpu),ClassVcpu,0)))} | C23: Hourly price of that class. If none covers, this is the largest-vCPU class on the list, and the flag says it does not cover.
A24: RDS storage GB | B24: =MAX(DbFloor,B6/1000000*DbPerM) | C24: At least the 20 GB floor.
A25: CloudWatch GB | B25: =B6/1000000*LogPerM | C25: Log GB per million requests times monthly requests.
A26: Data-transfer GB | B26: =B6*ReqKB*(1+RespMult)/1024/1024 | C26: Request plus response KB, converted to GB for the month.
A27: Secrets Manager secrets | B27: =SecretCount | C27: Fixed at 2. Not a second service.
A28: Fargate USD | B28: =B12*(B11*FargateCpuRate+B13*FargateMemRate)*Hours*3600 | C28: Tasks times (vCPU rate + memory rate) times 730 hours times 3,600 seconds.
A29: ALB hours USD | B29: =Hours*AlbHourly | C29: One load balancer, always on.
A30: ALB LCU USD | B30: =B19*LcuHourly*Hours | C30: Billed LCU times $0.008 times 730.
A31: Public IPv4 USD | B31: =B20*Ipv4Hourly*Hours | C31: Addresses times $0.005 times 730.
A32: RDS compute USD | B32: =B23*Hours | C32: Chosen class, Single-AZ, on-demand, 730 hours. No T4g CPU-credit overage.
A33: RDS storage USD | B33: =B24*Gp3Rate | C33: GB times $0.115. No extra gp3 throughput.
A34: Secrets Manager USD | B34: =SecretCount*SecretMonthly+SecretCalls/10000*SecretApiRate | C34: Two secrets at $0.40 plus 1,000 API calls.
A35: CloudWatch USD | B35: =MAX(0,B25-CwFreeGb)*(CwIngest+CwStore) | C35: $0 while log GB is inside 5. Above that, ingest plus archive on the excess only.
A36: Data transfer USD | B36: =MAX(0,B26-XferFreeGb)*XferRate | C36: GB above 100, times the regional $0.01 rate. See Rates for why this is not an internet-egress tier.
A37: NAT USD | B37: =IF(NatOn=1,Hours*NatHourly+B26*NatPerGb,0) | C37: $0 while NAT is off. On: 730 hours at $0.045 plus $0.045 per data-transfer GB.
A38: Multi-AZ, replicas, S3, Cognito, KMS vault, paid APM USD | B38: =0 | C38: Held at $0. Reasons are on the Inputs sheet. This is not a second architecture.
A39: Monthly total USD | B39: =B28+B29+B30+B31+B32+B33+B34+B35+B36+B37+B38 | C39: Exact sum of the lines above. Aurora is not included.
A40: Monthly total rounded to the cent | B40: =ROUND(B39,2) | C40: Round the exact sum. Do not add already-rounded lines. That is the penny in FIN-2026-10-02-01.
A41: Shape | B41: =IF(B9>TaskQuota*FargateMaxVcpu,"Larger shape",IF(B12>TaskQuota,"Larger shape",IF(B11>0.25,"One service, task size raised to stay under the tasks-per-service quota",IF(B12>ExpressMax,"One service, raise the Express max of 20 tasks","Fits one ECS Express service")))) | C41: Larger shape means past 5,000 tasks or past 5,000 times 32 vCPU. The row still prices the resources. It does not add a second service.
...

Sheet Rungs
A1: Rungs
A2: Each row is a formula case. Combined rows set all four volumes to the rung. Alone rows set one volume to the rung and hold the other three at 1,000. Multipliers, rates, and the NAT switch still come from Inputs and Rates, so editing those cells moves every rung. A row marked Larger shape prices the resources and does not invent a second service.
A4: Case | B4: Daily users | C4: Daily bots | D4: Daily offers | E4: Daily messages | F4: Daily requests | G4: Peak requests per second | H4: App vCPU at 60% | I4: DB vCPU at 60% | J4: Task vCPU | K4: Tasks | L4: Memory GB per task | M4: Total vCPU | N4: Total memory GB | O4: ALB LCU | P4: Public IPv4 | Q4: Connections | R4: RDS class | S4: RDS USD per hour | T4: Storage GB | U4: CloudWatch GB | V4: Data-transfer GB | W4: Fargate USD | X4: ALB hours USD | Y4: LCU USD | Z4: IPv4 USD | AA4: RDS USD | AB4: Storage USD | AC4: Secrets USD | AD4: CloudWatch USD | AE4: Data transfer USD | AF4: NAT USD | AG4: Held at zero USD | AH4: Total USD | AI4: Total rounded USD | AJ4: Shape | AK4: RDS cover | AL4: Fargate vCPU quota | AM4: Volume range | AN4: Aurora alternate USD
A5: All four at 1,000 | B5: 1000 | C5: 1000 | D5: 1000 | E5: 1000 | F5: =B5*ReqPerUser+C5*ReqPerBot+D5*ReqPerOffer+E5*ReqPerMessage | G5: =F5/86400*Peak | H5: =G5*AppVcpuS/CpuTarget | I5: =G5*DbVcpuS/CpuTarget | J5: =IF(MAX(1,ROUNDUP(H5/0.25,0))<=TaskQuota,0.25,IF(MAX(1,ROUNDUP(H5/0.5,0))<=TaskQuota,0.5,IF(MAX(1,ROUNDUP(H5/1,0))<=TaskQuota,1,IF(MAX(1,ROUNDUP(H5/2,0))<=TaskQuota,2,IF(MAX(1,ROUNDUP(H5/4,0))<=TaskQuota,4,IF(MAX(1,ROUNDUP(H5/8,0))<=TaskQuota,8,IF(MAX(1,ROUNDUP(H5/16,0))<=TaskQuota,16,32))))))) | K5: =MAX(1,ROUNDUP(H5/J5,0)) | L5: =IF(J5=0.25,0.5,IF(J5=0.5,1,IF(J5=1,2,IF(J5=2,4,IF(J5=4,8,IF(J5=8,16,IF(J5=16,32,60))))))) | M5: =K5*J5 | N5: =K5*L5 | O5: =MAX(MinLcu,G5/ReqPerConn/25,(G5/ReqPerConn)*HoldS/3000,G5*3600*ReqKB*(1+RespMult)/1024/1024) | P5: =AlbIpv4+IF(OR(NatOn=1,TaskPublicIp=0),0,K5) | Q5: =MAX(1,(G5/ReqPerConn)*HoldS) | R5: {=IFERROR(INDEX(ClassNames,MATCH(1,(ClassUse>=I5)*(ClassCap>=Q5),0)),"NO SINGLE-AZ CLASS")} | S5: {=IFERROR(INDEX(ClassPrices,MATCH(1,(ClassUse>=I5)*(ClassCap>=Q5),0)),INDEX(ClassPrices,MATCH(MAX(ClassVcpu),ClassVcpu,0)))} | T5: =MAX(DbFloor,F5*Hours/24/1000000*DbPerM) | U5: =F5*Hours/24/1000000*LogPerM | V5: =F5*Hours/24*ReqKB*(1+RespMult)/1024/1024 | W5: =K5*(J5*FargateCpuRate+L5*FargateMemRate)*Hours*3600 | X5: =Hours*AlbHourly | Y5: =O5*LcuHourly*Hours | Z5: =P5*Ipv4Hourly*Hours | AA5: =S5*Hours | AB5: =T5*Gp3Rate | AC5: =SecretCount*SecretMonthly+SecretCalls/10000*SecretApiRate | AD5: =MAX(0,U5-CwFreeGb)*(CwIngest+CwStore) | AE5: =MAX(0,V5-XferFreeGb)*XferRate | AF5: =IF(NatOn=1,Hours*NatHourly+V5*NatPerGb,0) | AG5: =0 | AH5: =W5+X5+Y5+Z5+AA5+AB5+AC5+AD5+AE5+AF5+AG5 | AI5: =ROUND(AH5,2) | AJ5: =IF(H5>TaskQuota*FargateMaxVcpu,"Larger shape",IF(K5>TaskQuota,"Larger shape",IF(J5>0.25,"One service, task size raised to stay under the tasks-per-service quota",IF(K5>ExpressMax,"One service, raise the Express max of 20 tasks","Fits one ECS Express service")))) | AK5: =IF(I5>MAX(ClassUse),"No single-AZ class covers the assumed CPU",IF(Q5>MAX(ClassCap),"No single-AZ class covers the assumed connections","Covered")) | AL5: =IF(M5>FargateVcpuQuota,"Above the default quota of 6 vCPU, which AWS marks adjustable","Inside the default quota of 6 vCPU") | AM5: =IF(OR(B5<1000,B5>10000000,C5<1000,C5>10000000,D5<1000,D5>10000000,E5<1000,E5>10000000),"Outside 1,000 to 10,000,000","In range") | AN5: =MAX(0.5,I5/AcuPerVcpu)*AuroraAcu*Hours+T5*AuroraGb
A6: All four at 10,000 | B6: 10000 | C6: 10000 | D6: 10000 | E6: 10000 | F6: =B6*ReqPerUser+C6*ReqPerBot+D6*ReqPerOffer+E6*ReqPerMessage | G6: =F6/86400*Peak | H6: =G6*AppVcpuS/CpuTarget | I6: =G6*DbVcpuS/CpuTarget | J6: =IF(MAX(1,ROUNDUP(H6/0.25,0))<=TaskQuota,0.25,IF(MAX(1,ROUNDUP(H6/0.5,0))<=TaskQuota,0.5,IF(MAX(1,ROUNDUP(H6/1,0))<=TaskQuota,1,IF(MAX(1,ROUNDUP(H6/2,0))<=TaskQuota,2,IF(MAX(1,ROUNDUP(H6/4,0))<=TaskQuota,4,IF(MAX(1,ROUNDUP(H6/8,0))<=TaskQuota,8,IF(MAX(1,ROUNDUP(H6/16,0))<=TaskQuota,16,32))))))) | K6: =MAX(1,ROUNDUP(H6/J6,0)) | L6: =IF(J6=0.25,0.5,IF(J6=0.5,1,IF(J6=1,2,IF(J6=2,4,IF(J6=4,8,IF(J6=8,16,IF(J6=16,32,60))))))) | M6: =K6*J6 | N6: =K6*L6 | O6: =MAX(MinLcu,G6/ReqPerConn/25,(G6/ReqPerConn)*HoldS/3000,G6*3600*ReqKB*(1+RespMult)/1024/1024) | P6: =AlbIpv4+IF(OR(NatOn=1,TaskPublicIp=0),0,K6) | Q6: =MAX(1,(G6/ReqPerConn)*HoldS) | R6: {=IFERROR(INDEX(ClassNames,MATCH(1,(ClassUse>=I6)*(ClassCap>=Q6),0)),"NO SINGLE-AZ CLASS")} | S6: {=IFERROR(INDEX(ClassPrices,MATCH(1,(ClassUse>=I6)*(ClassCap>=Q6),0)),INDEX(ClassPrices,MATCH(MAX(ClassVcpu),ClassVcpu,0)))} | T6: =MAX(DbFloor,F6*Hours/24/1000000*DbPerM) | U6: =F6*Hours/24/1000000*LogPerM | V6: =F6*Hours/24*ReqKB*(1+RespMult)/1024/1024 | W6: =K6*(J6*FargateCpuRate+L6*FargateMemRate)*Hours*3600 | X6: =Hours*AlbHourly | Y6: =O6*LcuHourly*Hours | Z6: =P6*Ipv4Hourly*Hours | AA6: =S6*Hours | AB6: =T6*Gp3Rate | AC6: =SecretCount*SecretMonthly+SecretCalls/10000*SecretApiRate | AD6: =MAX(0,U6-CwFreeGb)*(CwIngest+CwStore) | AE6: =MAX(0,V6-XferFreeGb)*XferRate | AF6: =IF(NatOn=1,Hours*NatHourly+V6*NatPerGb,0) | AG6: =0 | AH6: =W6+X6+Y6+Z6+AA6+AB6+AC6+AD6+AE6+AF6+AG6 | AI6: =ROUND(AH6,2) | AJ6: =IF(H6>TaskQuota*FargateMaxVcpu,"Larger shape",IF(K6>TaskQuota,"Larger shape",IF(J6>0.25,"One service, task size raised to stay under the tasks-per-service quota",IF(K6>ExpressMax,"One service, raise the Express max of 20 tasks","Fits one ECS Express service")))) | AK6: =IF(I6>MAX(ClassUse),"No single-AZ class covers the assumed CPU",IF(Q6>MAX(ClassCap),"No single-AZ class covers the assumed connections","Covered")) | AL6: =IF(M6>FargateVcpuQuota,"Above the default quota of 6 vCPU, which AWS marks adjustable","Inside the default quota of 6 vCPU") | AM6: =IF(OR(B6<1000,B6>10000000,C6<1000,C6>10000000,D6<1000,D6>10000000,E6<1000,E6>10000000),"Outside 1,000 to 10,000,000","In range") | AN6: =MAX(0.5,I6/AcuPerVcpu)*AuroraAcu*Hours+T6*AuroraGb
A7: All four at 100,000 | B7: 100000 | C7: 100000 | D7: 100000 | E7: 100000 | F7: =B7*ReqPerUser+C7*ReqPerBot+D7*ReqPerOffer+E7*ReqPerMessage | G7: =F7/86400*Peak | H7: =G7*AppVcpuS/CpuTarget | I7: =G7*DbVcpuS/CpuTarget | J7: =IF(MAX(1,ROUNDUP(H7/0.25,0))<=TaskQuota,0.25,IF(MAX(1,ROUNDUP(H7/0.5,0))<=TaskQuota,0.5,IF(MAX(1,ROUNDUP(H7/1,0))<=TaskQuota,1,IF(MAX(1,ROUNDUP(H7/2,0))<=TaskQuota,2,IF(MAX(1,ROUNDUP(H7/4,0))<=TaskQuota,4,IF(MAX(1,ROUNDUP(H7/8,0))<=TaskQuota,8,IF(MAX(1,ROUNDUP(H7/16,0))<=TaskQuota,16,32))))))) | K7: =MAX(1,ROUNDUP(H7/J7,0)) | L7: =IF(J7=0.25,0.5,IF(J7=0.5,1,IF(J7=1,2,IF(J7=2,4,IF(J7=4,8,IF(J7=8,16,IF(J7=16,32,60))))))) | M7: =K7*J7 | N7: =K7*L7 | O7: =MAX(MinLcu,G7/ReqPerConn/25,(G7/ReqPerConn)*HoldS/3000,G7*3600*ReqKB*(1+RespMult)/1024/1024) | P7: =AlbIpv4+IF(OR(NatOn=1,TaskPublicIp=0),0,K7) | Q7: =MAX(1,(G7/ReqPerConn)*HoldS) | R7: {=IFERROR(INDEX(ClassNames,MATCH(1,(ClassUse>=I7)*(ClassCap>=Q7),0)),"NO SINGLE-AZ CLASS")} | S7: {=IFERROR(INDEX(ClassPrices,MATCH(1,(ClassUse>=I7)*(ClassCap>=Q7),0)),INDEX(ClassPrices,MATCH(MAX(ClassVcpu),ClassVcpu,0)))} | T7: =MAX(DbFloor,F7*Hours/24/1000000*DbPerM) | U7: =F7*Hours/24/1000000*LogPerM | V7: =F7*Hours/24*ReqKB*(1+RespMult)/1024/1024 | W7: =K7*(J7*FargateCpuRate+L7*FargateMemRate)*Hours*3600 | X7: =Hours*AlbHourly | Y7: =O7*LcuHourly*Hours | Z7: =P7*Ipv4Hourly*Hours | AA7: =S7*Hours | AB7: =T7*Gp3Rate | AC7: =SecretCount*SecretMonthly+SecretCalls/10000*SecretApiRate | AD7: =MAX(0,U7-CwFreeGb)*(CwIngest+CwStore) | AE7: =MAX(0,V7-XferFreeGb)*XferRate | AF7: =IF(NatOn=1,Hours*NatHourly+V7*NatPerGb,0) | AG7: =0 | AH7: =W7+X7+Y7+Z7+AA7+AB7+AC7+AD7+AE7+AF7+AG7 | AI7: =ROUND(AH7,2) | AJ7: =IF(H7>TaskQuota*FargateMaxVcpu,"Larger shape",IF(K7>TaskQuota,"Larger shape",IF(J7>0.25,"One service, task size raised to stay under the tasks-per-service quota",IF(K7>ExpressMax,"One service, raise the Express max of 20 tasks","Fits one ECS Express service")))) | AK7: =IF(I7>MAX(ClassUse),"No single-AZ class covers the assumed CPU",IF(Q7>MAX(ClassCap),"No single-AZ class covers the assumed connections","Covered")) | AL7: =IF(M7>FargateVcpuQuota,"Above the default quota of 6 vCPU, which AWS marks adjustable","Inside the default quota of 6 vCPU") | AM7: =IF(OR(B7<1000,B7>10000000,C7<1000,C7>10000000,D7<1000,D7>10000000,E7<1000,E7>10000000),"Outside 1,000 to 10,000,000","In range") | AN7: =MAX(0.5,I7/AcuPerVcpu)*AuroraAcu*Hours+T7*AuroraGb
A8: All four at 1,000,000 | B8: 1000000 | C8: 1000000 | D8: 1000000 | E8: 1000000 | F8: =B8*ReqPerUser+C8*ReqPerBot+D8*ReqPerOffer+E8*ReqPerMessage | G8: =F8/86400*Peak | H8: =G8*AppVcpuS/CpuTarget | I8: =G8*DbVcpuS/CpuTarget | J8: =IF(MAX(1,ROUNDUP(H8/0.25,0))<=TaskQuota,0.25,IF(MAX(1,ROUNDUP(H8/0.5,0))<=TaskQuota,0.5,IF(MAX(1,ROUNDUP(H8/1,0))<=TaskQuota,1,IF(MAX(1,ROUNDUP(H8/2,0))<=TaskQuota,2,IF(MAX(1,ROUNDUP(H8/4,0))<=TaskQuota,4,IF(MAX(1,ROUNDUP(H8/8,0))<=TaskQuota,8,IF(MAX(1,ROUNDUP(H8/16,0))<=TaskQuota,16,32))))))) | K8: =MAX(1,ROUNDUP(H8/J8,0)) | L8: =IF(J8=0.25,0.5,IF(J8=0.5,1,IF(J8=1,2,IF(J8=2,4,IF(J8=4,8,IF(J8=8,16,IF(J8=16,32,60))))))) | M8: =K8*J8 | N8: =K8*L8 | O8: =MAX(MinLcu,G8/ReqPerConn/25,(G8/ReqPerConn)*HoldS/3000,G8*3600*ReqKB*(1+RespMult)/1024/1024) | P8: =AlbIpv4+IF(OR(NatOn=1,TaskPublicIp=0),0,K8) | Q8: =MAX(1,(G8/ReqPerConn)*HoldS) | R8: {=IFERROR(INDEX(ClassNames,MATCH(1,(ClassUse>=I8)*(ClassCap>=Q8),0)),"NO SINGLE-AZ CLASS")} | S8: {=IFERROR(INDEX(ClassPrices,MATCH(1,(ClassUse>=I8)*(ClassCap>=Q8),0)),INDEX(ClassPrices,MATCH(MAX(ClassVcpu),ClassVcpu,0)))} | T8: =MAX(DbFloor,F8*Hours/24/1000000*DbPerM) | U8: =F8*Hours/24/1000000*LogPerM | V8: =F8*Hours/24*ReqKB*(1+RespMult)/1024/1024 | W8: =K8*(J8*FargateCpuRate+L8*FargateMemRate)*Hours*3600 | X8: =Hours*AlbHourly | Y8: =O8*LcuHourly*Hours | Z8: =P8*Ipv4Hourly*Hours | AA8: =S8*Hours | AB8: =T8*Gp3Rate | AC8: =SecretCount*SecretMonthly+SecretCalls/10000*SecretApiRate | AD8: =MAX(0,U8-CwFreeGb)*(CwIngest+CwStore) | AE8: =MAX(0,V8-XferFreeGb)*XferRate | AF8: =IF(NatOn=1,Hours*NatHourly+V8*NatPerGb,0) | AG8: =0 | AH8: =W8+X8+Y8+Z8+AA8+AB8+AC8+AD8+AE8+AF8+AG8 | AI8: =ROUND(AH8,2) | AJ8: =IF(H8>TaskQuota*FargateMaxVcpu,"Larger shape",IF(K8>TaskQuota,"Larger shape",IF(J8>0.25,"One service, task size raised to stay under the tasks-per-service quota",IF(K8>ExpressMax,"One service, raise the Express max of 20 tasks","Fits one ECS Express service")))) | AK8: =IF(I8>MAX(ClassUse),"No single-AZ class covers the assumed CPU",IF(Q8>MAX(ClassCap),"No single-AZ class covers the assumed connections","Covered")) | AL8: =IF(M8>FargateVcpuQuota,"Above the default quota of 6 vCPU, which AWS marks adjustable","Inside the default quota of 6 vCPU") | AM8: =IF(OR(B8<1000,B8>10000000,C8<1000,C8>10000000,D8<1000,D8>10000000,E8<1000,E8>10000000),"Outside 1,000 to 10,000,000","In range") | AN8: =MAX(0.5,I8/AcuPerVcpu)*AuroraAcu*Hours+T8*AuroraGb
A9: All four at 10,000,000 | B9: 10000000 | C9: 10000000 | D9: 10000000 | E9: 10000000 | F9: =B9*ReqPerUser+C9*ReqPerBot+D9*ReqPerOffer+E9*ReqPerMessage | G9: =F9/86400*Peak | H9: =G9*AppVcpuS/CpuTarget | I9: =G9*DbVcpuS/CpuTarget | J9: =IF(MAX(1,ROUNDUP(H9/0.25,0))<=TaskQuota,0.25,IF(MAX(1,ROUNDUP(H9/0.5,0))<=TaskQuota,0.5,IF(MAX(1,ROUNDUP(H9/1,0))<=TaskQuota,1,IF(MAX(1,ROUNDUP(H9/2,0))<=TaskQuota,2,IF(MAX(1,ROUNDUP(H9/4,0))<=TaskQuota,4,IF(MAX(1,ROUNDUP(H9/8,0))<=TaskQuota,8,IF(MAX(1,ROUNDUP(H9/16,0))<=TaskQuota,16,32))))))) | K9: =MAX(1,ROUNDUP(H9/J9,0)) | L9: =IF(J9=0.25,0.5,IF(J9=0.5,1,IF(J9=1,2,IF(J9=2,4,IF(J9=4,8,IF(J9=8,16,IF(J9=16,32,60))))))) | M9: =K9*J9 | N9: =K9*L9 | O9: =MAX(MinLcu,G9/ReqPerConn/25,(G9/ReqPerConn)*HoldS/3000,G9*3600*ReqKB*(1+RespMult)/1024/1024) | P9: =AlbIpv4+IF(OR(NatOn=1,TaskPublicIp=0),0,K9) | Q9: =MAX(1,(G9/ReqPerConn)*HoldS) | R9: {=IFERROR(INDEX(ClassNames,MATCH(1,(ClassUse>=I9)*(ClassCap>=Q9),0)),"NO SINGLE-AZ CLASS")} | S9: {=IFERROR(INDEX(ClassPrices,MATCH(1,(ClassUse>=I9)*(ClassCap>=Q9),0)),INDEX(ClassPrices,MATCH(MAX(ClassVcpu),ClassVcpu,0)))} | T9: =MAX(DbFloor,F9*Hours/24/1000000*DbPerM) | U9: =F9*Hours/24/1000000*LogPerM | V9: =F9*Hours/24*ReqKB*(1+RespMult)/1024/1024 | W9: =K9*(J9*FargateCpuRate+L9*FargateMemRate)*Hours*3600 | X9: =Hours*AlbHourly | Y9: =O9*LcuHourly*Hours | Z9: =P9*Ipv4Hourly*Hours | AA9: =S9*Hours | AB9: =T9*Gp3Rate | AC9: =SecretCount*SecretMonthly+SecretCalls/10000*SecretApiRate | AD9: =MAX(0,U9-CwFreeGb)*(CwIngest+CwStore) | AE9: =MAX(0,V9-XferFreeGb)*XferRate | AF9: =IF(NatOn=1,Hours*NatHourly+V9*NatPerGb,0) | AG9: =0 | AH9: =W9+X9+Y9+Z9+AA9+AB9+AC9+AD9+AE9+AF9+AG9 | AI9: =ROUND(AH9,2) | AJ9: =IF(H9>TaskQuota*FargateMaxVcpu,"Larger shape",IF(K9>TaskQuota,"Larger shape",IF(J9>0.25,"One service, task size raised to stay under the tasks-per-service quota",IF(K9>ExpressMax,"One service, raise the Express max of 20 tasks","Fits one ECS Express service")))) | AK9: =IF(I9>MAX(ClassUse),"No single-AZ class covers the assumed CPU",IF(Q9>MAX(ClassCap),"No single-AZ class covers the assumed connections","Covered")) | AL9: =IF(M9>FargateVcpuQuota,"Above the default quota of 6 vCPU, which AWS marks adjustable","Inside the default quota of 6 vCPU") | AM9: =IF(OR(B9<1000,B9>10000000,C9<1000,C9>10000000,D9<1000,D9>10000000,E9<1000,E9>10000000),"Outside 1,000 to 10,000,000","In range") | AN9: =MAX(0.5,I9/AcuPerVcpu)*AuroraAcu*Hours+T9*AuroraGb
A10: Users alone at 1,000 | B10: 1000 | C10: 1000 | D10: 1000 | E10: 1000 | F10: =B10*ReqPerUser+C10*ReqPerBot+D10*ReqPerOffer+E10*ReqPerMessage | G10: =F10/86400*Peak | H10: =G10*AppVcpuS/CpuTarget | I10: =G10*DbVcpuS/CpuTarget | J10: =IF(MAX(1,ROUNDUP(H10/0.25,0))<=TaskQuota,0.25,IF(MAX(1,ROUNDUP(H10/0.5,0))<=TaskQuota,0.5,IF(MAX(1,ROUNDUP(H10/1,0))<=TaskQuota,1,IF(MAX(1,ROUNDUP(H10/2,0))<=TaskQuota,2,IF(MAX(1,ROUNDUP(H10/4,0))<=TaskQuota,4,IF(MAX(1,ROUNDUP(H10/8,0))<=TaskQuota,8,IF(MAX(1,ROUNDUP(H10/16,0))<=TaskQuota,16,32))))))) | K10: =MAX(1,ROUNDUP(H10/J10,0)) | L10: =IF(J10=0.25,0.5,IF(J10=0.5,1,IF(J10=1,2,IF(J10=2,4,IF(J10=4,8,IF(J10=8,16,IF(J10=16,32,60))))))) | M10: =K10*J10 | N10: =K10*L10 | O10: =MAX(MinLcu,G10/ReqPerConn/25,(G10/ReqPerConn)*HoldS/3000,G10*3600*ReqKB*(1+RespMult)/1024/1024) | P10: =AlbIpv4+IF(OR(NatOn=1,TaskPublicIp=0),0,K10) | Q10: =MAX(1,(G10/ReqPerConn)*HoldS) | R10: {=IFERROR(INDEX(ClassNames,MATCH(1,(ClassUse>=I10)*(ClassCap>=Q10),0)),"NO SINGLE-AZ CLASS")} | S10: {=IFERROR(INDEX(ClassPrices,MATCH(1,(ClassUse>=I10)*(ClassCap>=Q10),0)),INDEX(ClassPrices,MATCH(MAX(ClassVcpu),ClassVcpu,0)))} | T10: =MAX(DbFloor,F10*Hours/24/1000000*DbPerM) | U10: =F10*Hours/24/1000000*LogPerM | V10: =F10*Hours/24*ReqKB*(1+RespMult)/1024/1024 | W10: =K10*(J10*FargateCpuRate+L10*FargateMemRate)*Hours*3600 | X10: =Hours*AlbHourly | Y10: =O10*LcuHourly*Hours | Z10: =P10*Ipv4Hourly*Hours | AA10: =S10*Hours | AB10: =T10*Gp3Rate | AC10: =SecretCount*SecretMonthly+SecretCalls/10000*SecretApiRate | AD10: =MAX(0,U10-CwFreeGb)*(CwIngest+CwStore) | AE10: =MAX(0,V10-XferFreeGb)*XferRate | AF10: =IF(NatOn=1,Hours*NatHourly+V10*NatPerGb,0) | AG10: =0 | AH10: =W10+X10+Y10+Z10+AA10+AB10+AC10+AD10+AE10+AF10+AG10 | AI10: =ROUND(AH10,2) | AJ10: =IF(H10>TaskQuota*FargateMaxVcpu,"Larger shape",IF(K10>TaskQuota,"Larger shape",IF(J10>0.25,"One service, task size raised to stay under the tasks-per-service quota",IF(K10>ExpressMax,"One service, raise the Express max of 20 tasks","Fits one ECS Express service")))) | AK10: =IF(I10>MAX(ClassUse),"No single-AZ class covers the assumed CPU",IF(Q10>MAX(ClassCap),"No single-AZ class covers the assumed connections","Covered")) | AL10: =IF(M10>FargateVcpuQuota,"Above the default quota of 6 vCPU, which AWS marks adjustable","Inside the default quota of 6 vCPU") | AM10: =IF(OR(B10<1000,B10>10000000,C10<1000,C10>10000000,D10<1000,D10>10000000,E10<1000,E10>10000000),"Outside 1,000 to 10,000,000","In range") | AN10: =MAX(0.5,I10/AcuPerVcpu)*AuroraAcu*Hours+T10*AuroraGb
A11: Users alone at 10,000 | B11: 10000 | C11: 1000 | D11: 1000 | E11: 1000 | F11: =B11*ReqPerUser+C11*ReqPerBot+D11*ReqPerOffer+E11*ReqPerMessage | G11: =F11/86400*Peak | H11: =G11*AppVcpuS/CpuTarget | I11: =G11*DbVcpuS/CpuTarget | J11: =IF(MAX(1,ROUNDUP(H11/0.25,0))<=TaskQuota,0.25,IF(MAX(1,ROUNDUP(H11/0.5,0))<=TaskQuota,0.5,IF(MAX(1,ROUNDUP(H11/1,0))<=TaskQuota,1,IF(MAX(1,ROUNDUP(H11/2,0))<=TaskQuota,2,IF(MAX(1,ROUNDUP(H11/4,0))<=TaskQuota,4,IF(MAX(1,ROUNDUP(H11/8,0))<=TaskQuota,8,IF(MAX(1,ROUNDUP(H11/16,0))<=TaskQuota,16,32))))))) | K11: =MAX(1,ROUNDUP(H11/J11,0)) | L11: =IF(J11=0.25,0.5,IF(J11=0.5,1,IF(J11=1,2,IF(J11=2,4,IF(J11=4,8,IF(J11=8,16,IF(J11=16,32,60))))))) | M11: =K11*J11 | N11: =K11*L11 | O11: =MAX(MinLcu,G11/ReqPerConn/25,(G11/ReqPerConn)*HoldS/3000,G11*3600*ReqKB*(1+RespMult)/1024/1024) | P11: =AlbIpv4+IF(OR(NatOn=1,TaskPublicIp=0),0,K11) | Q11: =MAX(1,(G11/ReqPerConn)*HoldS) | R11: {=IFERROR(INDEX(ClassNames,MATCH(1,(ClassUse>=I11)*(ClassCap>=Q11),0)),"NO SINGLE-AZ CLASS")} | S11: {=IFERROR(INDEX(ClassPrices,MATCH(1,(ClassUse>=I11)*(ClassCap>=Q11),0)),INDEX(ClassPrices,MATCH(MAX(ClassVcpu),ClassVcpu,0)))} | T11: =MAX(DbFloor,F11*Hours/24/1000000*DbPerM) | U11: =F11*Hours/24/1000000*LogPerM | V11: =F11*Hours/24*ReqKB*(1+RespMult)/1024/1024 | W11: =K11*(J11*FargateCpuRate+L11*FargateMemRate)*Hours*3600 | X11: =Hours*AlbHourly | Y11: =O11*LcuHourly*Hours | Z11: =P11*Ipv4Hourly*Hours | AA11: =S11*Hours | AB11: =T11*Gp3Rate | AC11: =SecretCount*SecretMonthly+SecretCalls/10000*SecretApiRate | AD11: =MAX(0,U11-CwFreeGb)*(CwIngest+CwStore) | AE11: =MAX(0,V11-XferFreeGb)*XferRate | AF11: =IF(NatOn=1,Hours*NatHourly+V11*NatPerGb,0) | AG11: =0 | AH11: =W11+X11+Y11+Z11+AA11+AB11+AC11+AD11+AE11+AF11+AG11 | AI11: =ROUND(AH11,2) | AJ11: =IF(H11>TaskQuota*FargateMaxVcpu,"Larger shape",IF(K11>TaskQuota,"Larger shape",IF(J11>0.25,"One service, task size raised to stay under the tasks-per-service quota",IF(K11>ExpressMax,"One service, raise the Express max of 20 tasks","Fits one ECS Express service")))) | AK11: =IF(I11>MAX(ClassUse),"No single-AZ class covers the assumed CPU",IF(Q11>MAX(ClassCap),"No single-AZ class covers the assumed connections","Covered")) | AL11: =IF(M11>FargateVcpuQuota,"Above the default quota of 6 vCPU, which AWS marks adjustable","Inside the default quota of 6 vCPU") | AM11: =IF(OR(B11<1000,B11>10000000,C11<1000,C11>10000000,D11<1000,D11>10000000,E11<1000,E11>10000000),"Outside 1,000 to 10,000,000","In range") | AN11: =MAX(0.5,I11/AcuPerVcpu)*AuroraAcu*Hours+T11*AuroraGb
A12: Users alone at 100,000 | B12: 100000 | C12: 1000 | D12: 1000 | E12: 1000 | F12: =B12*ReqPerUser+C12*ReqPerBot+D12*ReqPerOffer+E12*ReqPerMessage | G12: =F12/86400*Peak | H12: =G12*AppVcpuS/CpuTarget | I12: =G12*DbVcpuS/CpuTarget | J12: =IF(MAX(1,ROUNDUP(H12/0.25,0))<=TaskQuota,0.25,IF(MAX(1,ROUNDUP(H12/0.5,0))<=TaskQuota,0.5,IF(MAX(1,ROUNDUP(H12/1,0))<=TaskQuota,1,IF(MAX(1,ROUNDUP(H12/2,0))<=TaskQuota,2,IF(MAX(1,ROUNDUP(H12/4,0))<=TaskQuota,4,IF(MAX(1,ROUNDUP(H12/8,0))<=TaskQuota,8,IF(MAX(1,ROUNDUP(H12/16,0))<=TaskQuota,16,32))))))) | K12: =MAX(1,ROUNDUP(H12/J12,0)) | L12: =IF(J12=0.25,0.5,IF(J12=0.5,1,IF(J12=1,2,IF(J12=2,4,IF(J12=4,8,IF(J12=8,16,IF(J12=16,32,60))))))) | M12: =K12*J12 | N12: =K12*L12 | O12: =MAX(MinLcu,G12/ReqPerConn/25,(G12/ReqPerConn)*HoldS/3000,G12*3600*ReqKB*(1+RespMult)/1024/1024) | P12: =AlbIpv4+IF(OR(NatOn=1,TaskPublicIp=0),0,K12) | Q12: =MAX(1,(G12/ReqPerConn)*HoldS) | R12: {=IFERROR(INDEX(ClassNames,MATCH(1,(ClassUse>=I12)*(ClassCap>=Q12),0)),"NO SINGLE-AZ CLASS")} | S12: {=IFERROR(INDEX(ClassPrices,MATCH(1,(ClassUse>=I12)*(ClassCap>=Q12),0)),INDEX(ClassPrices,MATCH(MAX(ClassVcpu),ClassVcpu,0)))} | T12: =MAX(DbFloor,F12*Hours/24/1000000*DbPerM) | U12: =F12*Hours/24/1000000*LogPerM | V12: =F12*Hours/24*ReqKB*(1+RespMult)/1024/1024 | W12: =K12*(J12*FargateCpuRate+L12*FargateMemRate)*Hours*3600 | X12: =Hours*AlbHourly | Y12: =O12*LcuHourly*Hours | Z12: =P12*Ipv4Hourly*Hours | AA12: =S12*Hours | AB12: =T12*Gp3Rate | AC12: =SecretCount*SecretMonthly+SecretCalls/10000*SecretApiRate | AD12: =MAX(0,U12-CwFreeGb)*(CwIngest+CwStore) | AE12: =MAX(0,V12-XferFreeGb)*XferRate | AF12: =IF(NatOn=1,Hours*NatHourly+V12*NatPerGb,0) | AG12: =0 | AH12: =W12+X12+Y12+Z12+AA12+AB12+AC12+AD12+AE12+AF12+AG12 | AI12: =ROUND(AH12,2) | AJ12: =IF(H12>TaskQuota*FargateMaxVcpu,"Larger shape",IF(K12>TaskQuota,"Larger shape",IF(J12>0.25,"One service, task size raised to stay under the tasks-per-service quota",IF(K12>ExpressMax,"One service, raise the Express max of 20 tasks","Fits one ECS Express service")))) | AK12: =IF(I12>MAX(ClassUse),"No single-AZ class covers the assumed CPU",IF(Q12>MAX(ClassCap),"No single-AZ class covers the assumed connections","Covered")) | AL12: =IF(M12>FargateVcpuQuota,"Above the default quota of 6 vCPU, which AWS marks adjustable","Inside the default quota of 6 vCPU") | AM12: =IF(OR(B12<1000,B12>10000000,C12<1000,C12>10000000,D12<1000,D12>10000000,E12<1000,E12>10000000),"Outside 1,000 to 10,000,000","In range") | AN12: =MAX(0.5,I12/AcuPerVcpu)*AuroraAcu*Hours+T12*AuroraGb
A13: Users alone at 1,000,000 | B13: 1000000 | C13: 1000 | D13: 1000 | E13: 1000 | F13: =B13*ReqPerUser+C13*ReqPerBot+D13*ReqPerOffer+E13*ReqPerMessage | G13: =F13/86400*Peak | H13: =G13*AppVcpuS/CpuTarget | I13: =G13*DbVcpuS/CpuTarget | J13: =IF(MAX(1,ROUNDUP(H13/0.25,0))<=TaskQuota,0.25,IF(MAX(1,ROUNDUP(H13/0.5,0))<=TaskQuota,0.5,IF(MAX(1,ROUNDUP(H13/1,0))<=TaskQuota,1,IF(MAX(1,ROUNDUP(H13/2,0))<=TaskQuota,2,IF(MAX(1,ROUNDUP(H13/4,0))<=TaskQuota,4,IF(MAX(1,ROUNDUP(H13/8,0))<=TaskQuota,8,IF(MAX(1,ROUNDUP(H13/16,0))<=TaskQuota,16,32))))))) | K13: =MAX(1,ROUNDUP(H13/J13,0)) | L13: =IF(J13=0.25,0.5,IF(J13=0.5,1,IF(J13=1,2,IF(J13=2,4,IF(J13=4,8,IF(J13=8,16,IF(J13=16,32,60))))))) | M13: =K13*J13 | N13: =K13*L13 | O13: =MAX(MinLcu,G13/ReqPerConn/25,(G13/ReqPerConn)*HoldS/3000,G13*3600*ReqKB*(1+RespMult)/1024/1024) | P13: =AlbIpv4+IF(OR(NatOn=1,TaskPublicIp=0),0,K13) | Q13: =MAX(1,(G13/ReqPerConn)*HoldS) | R13: {=IFERROR(INDEX(ClassNames,MATCH(1,(ClassUse>=I13)*(ClassCap>=Q13),0)),"NO SINGLE-AZ CLASS")} | S13: {=IFERROR(INDEX(ClassPrices,MATCH(1,(ClassUse>=I13)*(ClassCap>=Q13),0)),INDEX(ClassPrices,MATCH(MAX(ClassVcpu),ClassVcpu,0)))} | T13: =MAX(DbFloor,F13*Hours/24/1000000*DbPerM) | U13: =F13*Hours/24/1000000*LogPerM | V13: =F13*Hours/24*ReqKB*(1+RespMult)/1024/1024 | W13: =K13*(J13*FargateCpuRate+L13*FargateMemRate)*Hours*3600 | X13: =Hours*AlbHourly | Y13: =O13*LcuHourly*Hours | Z13: =P13*Ipv4Hourly*Hours | AA13: =S13*Hours | AB13: =T13*Gp3Rate | AC13: =SecretCount*SecretMonthly+SecretCalls/10000*SecretApiRate | AD13: =MAX(0,U13-CwFreeGb)*(CwIngest+CwStore) | AE13: =MAX(0,V13-XferFreeGb)*XferRate | AF13: =IF(NatOn=1,Hours*NatHourly+V13*NatPerGb,0) | AG13: =0 | AH13: =W13+X13+Y13+Z13+AA13+AB13+AC13+AD13+AE13+AF13+AG13 | AI13: =ROUND(AH13,2) | AJ13: =IF(H13>TaskQuota*FargateMaxVcpu,"Larger shape",IF(K13>TaskQuota,"Larger shape",IF(J13>0.25,"One service, task size raised to stay under the tasks-per-service quota",IF(K13>ExpressMax,"One service, raise the Express max of 20 tasks","Fits one ECS Express service")))) | AK13: =IF(I13>MAX(ClassUse),"No single-AZ class covers the assumed CPU",IF(Q13>MAX(ClassCap),"No single-AZ class covers the assumed connections","Covered")) | AL13: =IF(M13>FargateVcpuQuota,"Above the default quota of 6 vCPU, which AWS marks adjustable","Inside the default quota of 6 vCPU") | AM13: =IF(OR(B13<1000,B13>10000000,C13<1000,C13>10000000,D13<1000,D13>10000000,E13<1000,E13>10000000),"Outside 1,000 to 10,000,000","In range") | AN13: =MAX(0.5,I13/AcuPerVcpu)*AuroraAcu*Hours+T13*AuroraGb
A14: Users alone at 10,000,000 | B14: 10000000 | C14: 1000 | D14: 1000 | E14: 1000 | F14: =B14*ReqPerUser+C14*ReqPerBot+D14*ReqPerOffer+E14*ReqPerMessage | G14: =F14/86400*Peak | H14: =G14*AppVcpuS/CpuTarget | I14: =G14*DbVcpuS/CpuTarget | J14: =IF(MAX(1,ROUNDUP(H14/0.25,0))<=TaskQuota,0.25,IF(MAX(1,ROUNDUP(H14/0.5,0))<=TaskQuota,0.5,IF(MAX(1,ROUNDUP(H14/1,0))<=TaskQuota,1,IF(MAX(1,ROUNDUP(H14/2,0))<=TaskQuota,2,IF(MAX(1,ROUNDUP(H14/4,0))<=TaskQuota,4,IF(MAX(1,ROUNDUP(H14/8,0))<=TaskQuota,8,IF(MAX(1,ROUNDUP(H14/16,0))<=TaskQuota,16,32))))))) | K14: =MAX(1,ROUNDUP(H14/J14,0)) | L14: =IF(J14=0.25,0.5,IF(J14=0.5,1,IF(J14=1,2,IF(J14=2,4,IF(J14=4,8,IF(J14=8,16,IF(J14=16,32,60))))))) | M14: =K14*J14 | N14: =K14*L14 | O14: =MAX(MinLcu,G14/ReqPerConn/25,(G14/ReqPerConn)*HoldS/3000,G14*3600*ReqKB*(1+RespMult)/1024/1024) | P14: =AlbIpv4+IF(OR(NatOn=1,TaskPublicIp=0),0,K14) | Q14: =MAX(1,(G14/ReqPerConn)*HoldS) | R14: {=IFERROR(INDEX(ClassNames,MATCH(1,(ClassUse>=I14)*(ClassCap>=Q14),0)),"NO SINGLE-AZ CLASS")} | S14: {=IFERROR(INDEX(ClassPrices,MATCH(1,(ClassUse>=I14)*(ClassCap>=Q14),0)),INDEX(ClassPrices,MATCH(MAX(ClassVcpu),ClassVcpu,0)))} | T14: =MAX(DbFloor,F14*Hours/24/1000000*DbPerM) | U14: =F14*Hours/24/1000000*LogPerM | V14: =F14*Hours/24*ReqKB*(1+RespMult)/1024/1024 | W14: =K14*(J14*FargateCpuRate+L14*FargateMemRate)*Hours*3600 | X14: =Hours*AlbHourly | Y14: =O14*LcuHourly*Hours | Z14: =P14*Ipv4Hourly*Hours | AA14: =S14*Hours | AB14: =T14*Gp3Rate | AC14: =SecretCount*SecretMonthly+SecretCalls/10000*SecretApiRate | AD14: =MAX(0,U14-CwFreeGb)*(CwIngest+CwStore) | AE14: =MAX(0,V14-XferFreeGb)*XferRate | AF14: =IF(NatOn=1,Hours*NatHourly+V14*NatPerGb,0) | AG14: =0 | AH14: =W14+X14+Y14+Z14+AA14+AB14+AC14+AD14+AE14+AF14+AG14 | AI14: =ROUND(AH14,2) | AJ14: =IF(H14>TaskQuota*FargateMaxVcpu,"Larger shape",IF(K14>TaskQuota,"Larger shape",IF(J14>0.25,"One service, task size raised to stay under the tasks-per-service quota",IF(K14>ExpressMax,"One service, raise the Express max of 20 tasks","Fits one ECS Express service")))) | AK14: =IF(I14>MAX(ClassUse),"No single-AZ class covers the assumed CPU",IF(Q14>MAX(ClassCap),"No single-AZ class covers the assumed connections","Covered")) | AL14: =IF(M14>FargateVcpuQuota,"Above the default quota of 6 vCPU, which AWS marks adjustable","Inside the default quota of 6 vCPU") | AM14: =IF(OR(B14<1000,B14>10000000,C14<1000,C14>10000000,D14<1000,D14>10000000,E14<1000,E14>10000000),"Outside 1,000 to 10,000,000","In range") | AN14: =MAX(0.5,I14/AcuPerVcpu)*AuroraAcu*Hours+T14*AuroraGb
A15: Bots alone at 1,000 | B15: 1000 | C15: 1000 | D15: 1000 | E15: 1000 | F15: =B15*ReqPerUser+C15*ReqPerBot+D15*ReqPerOffer+E15*ReqPerMessage | G15: =F15/86400*Peak | H15: =G15*AppVcpuS/CpuTarget | I15: =G15*DbVcpuS/CpuTarget | J15: =IF(MAX(1,ROUNDUP(H15/0.25,0))<=TaskQuota,0.25,IF(MAX(1,ROUNDUP(H15/0.5,0))<=TaskQuota,0.5,IF(MAX(1,ROUNDUP(H15/1,0))<=TaskQuota,1,IF(MAX(1,ROUNDUP(H15/2,0))<=TaskQuota,2,IF(MAX(1,ROUNDUP(H15/4,0))<=TaskQuota,4,IF(MAX(1,ROUNDUP(H15/8,0))<=TaskQuota,8,IF(MAX(1,ROUNDUP(H15/16,0))<=TaskQuota,16,32))))))) | K15: =MAX(1,ROUNDUP(H15/J15,0)) | L15: =IF(J15=0.25,0.5,IF(J15=0.5,1,IF(J15=1,2,IF(J15=2,4,IF(J15=4,8,IF(J15=8,16,IF(J15=16,32,60))))))) | M15: =K15*J15 | N15: =K15*L15 | O15: =MAX(MinLcu,G15/ReqPerConn/25,(G15/ReqPerConn)*HoldS/3000,G15*3600*ReqKB*(1+RespMult)/1024/1024) | P15: =AlbIpv4+IF(OR(NatOn=1,TaskPublicIp=0),0,K15) | Q15: =MAX(1,(G15/ReqPerConn)*HoldS) | R15: {=IFERROR(INDEX(ClassNames,MATCH(1,(ClassUse>=I15)*(ClassCap>=Q15),0)),"NO SINGLE-AZ CLASS")} | S15: {=IFERROR(INDEX(ClassPrices,MATCH(1,(ClassUse>=I15)*(ClassCap>=Q15),0)),INDEX(ClassPrices,MATCH(MAX(ClassVcpu),ClassVcpu,0)))} | T15: =MAX(DbFloor,F15*Hours/24/1000000*DbPerM) | U15: =F15*Hours/24/1000000*LogPerM | V15: =F15*Hours/24*ReqKB*(1+RespMult)/1024/1024 | W15: =K15*(J15*FargateCpuRate+L15*FargateMemRate)*Hours*3600 | X15: =Hours*AlbHourly | Y15: =O15*LcuHourly*Hours | Z15: =P15*Ipv4Hourly*Hours | AA15: =S15*Hours | AB15: =T15*Gp3Rate | AC15: =SecretCount*SecretMonthly+SecretCalls/10000*SecretApiRate | AD15: =MAX(0,U15-CwFreeGb)*(CwIngest+CwStore) | AE15: =MAX(0,V15-XferFreeGb)*XferRate | AF15: =IF(NatOn=1,Hours*NatHourly+V15*NatPerGb,0) | AG15: =0 | AH15: =W15+X15+Y15+Z15+AA15+AB15+AC15+AD15+AE15+AF15+AG15 | AI15: =ROUND(AH15,2) | AJ15: =IF(H15>TaskQuota*FargateMaxVcpu,"Larger shape",IF(K15>TaskQuota,"Larger shape",IF(J15>0.25,"One service, task size raised to stay under the tasks-per-service quota",IF(K15>ExpressMax,"One service, raise the Express max of 20 tasks","Fits one ECS Express service")))) | AK15: =IF(I15>MAX(ClassUse),"No single-AZ class covers the assumed CPU",IF(Q15>MAX(ClassCap),"No single-AZ class covers the assumed connections","Covered")) | AL15: =IF(M15>FargateVcpuQuota,"Above the default quota of 6 vCPU, which AWS marks adjustable","Inside the default quota of 6 vCPU") | AM15: =IF(OR(B15<1000,B15>10000000,C15<1000,C15>10000000,D15<1000,D15>10000000,E15<1000,E15>10000000),"Outside 1,000 to 10,000,000","In range") | AN15: =MAX(0.5,I15/AcuPerVcpu)*AuroraAcu*Hours+T15*AuroraGb
A16: Bots alone at 10,000 | B16: 1000 | C16: 10000 | D16: 1000 | E16: 1000 | F16: =B16*ReqPerUser+C16*ReqPerBot+D16*ReqPerOffer+E16*ReqPerMessage | G16: =F16/86400*Peak | H16: =G16*AppVcpuS/CpuTarget | I16: =G16*DbVcpuS/CpuTarget | J16: =IF(MAX(1,ROUNDUP(H16/0.25,0))<=TaskQuota,0.25,IF(MAX(1,ROUNDUP(H16/0.5,0))<=TaskQuota,0.5,IF(MAX(1,ROUNDUP(H16/1,0))<=TaskQuota,1,IF(MAX(1,ROUNDUP(H16/2,0))<=TaskQuota,2,IF(MAX(1,ROUNDUP(H16/4,0))<=TaskQuota,4,IF(MAX(1,ROUNDUP(H16/8,0))<=TaskQuota,8,IF(MAX(1,ROUNDUP(H16/16,0))<=TaskQuota,16,32))))))) | K16: =MAX(1,ROUNDUP(H16/J16,0)) | L16: =IF(J16=0.25,0.5,IF(J16=0.5,1,IF(J16=1,2,IF(J16=2,4,IF(J16=4,8,IF(J16=8,16,IF(J16=16,32,60))))))) | M16: =K16*J16 | N16: =K16*L16 | O16: =MAX(MinLcu,G16/ReqPerConn/25,(G16/ReqPerConn)*HoldS/3000,G16*3600*ReqKB*(1+RespMult)/1024/1024) | P16: =AlbIpv4+IF(OR(NatOn=1,TaskPublicIp=0),0,K16) | Q16: =MAX(1,(G16/ReqPerConn)*HoldS) | R16: {=IFERROR(INDEX(ClassNames,MATCH(1,(ClassUse>=I16)*(ClassCap>=Q16),0)),"NO SINGLE-AZ CLASS")} | S16: {=IFERROR(INDEX(ClassPrices,MATCH(1,(ClassUse>=I16)*(ClassCap>=Q16),0)),INDEX(ClassPrices,MATCH(MAX(ClassVcpu),ClassVcpu,0)))} | T16: =MAX(DbFloor,F16*Hours/24/1000000*DbPerM) | U16: =F16*Hours/24/1000000*LogPerM | V16: =F16*Hours/24*ReqKB*(1+RespMult)/1024/1024 | W16: =K16*(J16*FargateCpuRate+L16*FargateMemRate)*Hours*3600 | X16: =Hours*AlbHourly | Y16: =O16*LcuHourly*Hours | Z16: =P16*Ipv4Hourly*Hours | AA16: =S16*Hours | AB16: =T16*Gp3Rate | AC16: =SecretCount*SecretMonthly+SecretCalls/10000*SecretApiRate | AD16: =MAX(0,U16-CwFreeGb)*(CwIngest+CwStore) | AE16: =MAX(0,V16-XferFreeGb)*XferRate | AF16: =IF(NatOn=1,Hours*NatHourly+V16*NatPerGb,0) | AG16: =0 | AH16: =W16+X16+Y16+Z16+AA16+AB16+AC16+AD16+AE16+AF16+AG16 | AI16: =ROUND(AH16,2) | AJ16: =IF(H16>TaskQuota*FargateMaxVcpu,"Larger shape",IF(K16>TaskQuota,"Larger shape",IF(J16>0.25,"One service, task size raised to stay under the tasks-per-service quota",IF(K16>ExpressMax,"One service, raise the Express max of 20 tasks","Fits one ECS Express service")))) | AK16: =IF(I16>MAX(ClassUse),"No single-AZ class covers the assumed CPU",IF(Q16>MAX(ClassCap),"No single-AZ class covers the assumed connections","Covered")) | AL16: =IF(M16>FargateVcpuQuota,"Above the default quota of 6 vCPU, which AWS marks adjustable","Inside the default quota of 6 vCPU") | AM16: =IF(OR(B16<1000,B16>10000000,C16<1000,C16>10000000,D16<1000,D16>10000000,E16<1000,E16>10000000),"Outside 1,000 to 10,000,000","In range") | AN16: =MAX(0.5,I16/AcuPerVcpu)*AuroraAcu*Hours+T16*AuroraGb
... A29: Messages alone at 10,000,000 | B29: 1000 | C29: 1000 | D29: 1000 | E29: 10000000 | F29: =B29*ReqPerUser+C29*ReqPerBot+D29*ReqPerOffer+E29*ReqPerMessage | G29: =F29/86400*Peak | H29: =G29*AppVcpuS/CpuTarget | I29: =G29*DbVcpuS/CpuTarget | J29: =IF(MAX(1,ROUNDUP(H29/0.25,0))<=TaskQuota,0.25,IF(MAX(1,ROUNDUP(H29/0.5,0))<=TaskQuota,0.5,IF(MAX(1,ROUNDUP(H29/1,0))<=TaskQuota,1,IF(MAX(1,ROUNDUP(H29/2,0))<=TaskQuota,2,IF(MAX(1,ROUNDUP(H29/4,0))<=TaskQuota,4,IF(MAX(1,ROUNDUP(H29/8,0))<=TaskQuota,8,IF(MAX(1,ROUNDUP(H29/16,0))<=TaskQuota,16,32))))))) | K29: =MAX(1,ROUNDUP(H29/J29,0)) | L29: =IF(J29=0.25,0.5,IF(J29=0.5,1,IF(J29=1,2,IF(J29=2,4,IF(J29=4,8,IF(J29=8,16,IF(J29=16,32,60))))))) | M29: =K29*J29 | N29: =K29*L29 | O29: =MAX(MinLcu,G29/ReqPerConn/25,(G29/ReqPerConn)*HoldS/3000,G29*3600*ReqKB*(1+RespMult)/1024/1024) | P29: =AlbIpv4+IF(OR(NatOn=1,TaskPublicIp=0),0,K29) | Q29: =MAX(1,(G29/ReqPerConn)*HoldS) | R29: {=IFERROR(INDEX(ClassNames,MATCH(1,(ClassUse>=I29)*(ClassCap>=Q29),0)),"NO SINGLE-AZ CLASS")} | S29: {=IFERROR(INDEX(ClassPrices,MATCH(1,(ClassUse>=I29)*(ClassCap>=Q29),0)),INDEX(ClassPrices,MATCH(MAX(ClassVcpu),ClassVcpu,0)))} | T29: =MAX(DbFloor,F29*Hours/24/1000000*DbPerM) | U29: =F29*Hours/24/1000000*LogPerM | V29: =F29*Hours/24*ReqKB*(1+RespMult)/1024/1024 | W29: =K29*(J29*FargateCpuRate+L29*FargateMemRate)*Hours*3600 | X29: =Hours*AlbHourly | Y29: =O29*LcuHourly*Hours | Z29: =P29*Ipv4Hourly*Hours | AA29: =S29*Hours | AB29: =T29*Gp3Rate | AC29: =SecretCount*SecretMonthly+SecretCalls/10000*SecretApiRate | AD29: =MAX(0,U29-CwFreeGb)*(CwIngest+CwStore) | AE29: =MAX(0,V29-XferFreeGb)*XferRate | AF29: =IF(NatOn=1,Hours*NatHourly+V29*NatPerGb,0) | AG29: =0 | AH29: =W29+X29+Y29+Z29+AA29+AB29+AC29+AD29+AE29+AF29+AG29 | AI29: =ROUND(AH29,2) | AJ29: =IF(H29>TaskQuota*FargateMaxVcpu,"Larger shape",IF(K29>TaskQuota,"Larger shape",IF(J29>0.25,"One service, task size raised to stay under the tasks-per-service quota",IF(K29>ExpressMax,"One service, raise the Express max of 20 tasks","Fits one ECS Express service")))) | AK29: =IF(I29>MAX(ClassUse),"No single-AZ class covers the assumed CPU",IF(Q29>MAX(ClassCap),"No single-AZ class covers the assumed connections","Covered")) | AL29: =IF(M29>FargateVcpuQuota,"Above the default quota of 6 vCPU, which AWS marks adjustable","Inside the default quota of 6 vCPU") | AM29: =IF(OR(B29<1000,B29>10000000,C29<1000,C29>10000000,D29<1000,D29>10000000,E29<1000,E29>10000000),"Outside 1,000 to 10,000,000","In range") | AN29: =MAX(0.5,I29/AcuPerVcpu)*AuroraAcu*Hours+T29*AuroraGb

Sheet Breakpoints
A1: Where one ECS Express service stops fitting
A2: These volumes use the current Inputs multipliers, with all four daily volumes set equal. They are formulas. The default max of 20 tasks is a setting AWS says can be raised. The hard stop is the tasks-per-service quota of 5,000, which is not adjustable, or a task bigger than 32 vCPU, which Fargate does not offer. Past a hard marker the Rungs sheet says Larger shape and still prices one pool of tasks. It does not add a second service.
A4: Marker | B4: Combined daily volume where it binds | C4: What it is | D4: Cite
A5: Express default max of 20 tasks at 0.25 vCPU | B5: =IF((ReqPerUser+ReqPerBot+ReqPerOffer+ReqPerMessage)=0,"n/a",(ExpressMax*0.25)*CpuTarget/AppVcpuS/Peak*86400/(ReqPerUser+ReqPerBot+ReqPerOffer+ReqPerMessage)) | C5: Above this, one service still fits if the max-task setting is raised. Not a hard stop. | D5: https://docs.aws.amazon.com/AmazonECS/latest/developerguide/express-service-work.html
A6: Default Fargate On-Demand vCPU quota of 6 | B6: =IF((ReqPerUser+ReqPerBot+ReqPerOffer+ReqPerMessage)=0,"n/a",(FargateVcpuQuota)*CpuTarget/AppVcpuS/Peak*86400/(ReqPerUser+ReqPerBot+ReqPerOffer+ReqPerMessage)) | C6: Account quota. AWS marks it adjustable. Not a hard stop. | D6: https://docs.aws.amazon.com/general/latest/gr/ecs-service.html
A7: 5,000 tasks at 0.25 vCPU | B7: =IF((ReqPerUser+ReqPerBot+ReqPerOffer+ReqPerMessage)=0,"n/a",(TaskQuota*0.25)*CpuTarget/AppVcpuS/Peak*86400/(ReqPerUser+ReqPerBot+ReqPerOffer+ReqPerMessage)) | C7: The tasks-per-service quota if every task stays at the smallest size. The model raises task size before it calls this a hard stop. | D7: https://docs.aws.amazon.com/general/latest/gr/ecs-service.html
A8: Hard stop: 5,000 tasks at 32 vCPU | B8: =IF((ReqPerUser+ReqPerBot+ReqPerOffer+ReqPerMessage)=0,"n/a",(TaskQuota*FargateMaxVcpu)*CpuTarget/AppVcpuS/Peak*86400/(ReqPerUser+ReqPerBot+ReqPerOffer+ReqPerMessage)) | C8: One service cannot hold more compute than 5,000 tasks of 32 vCPU. Past this the row is a larger shape. | D8: https://docs.aws.amazon.com/general/latest/gr/ecs-service.html
A10: Date read for both quota pages and the Express page: 2026-10-02.

Sheet Reconcile
A1: Floor against FIN-2026-10-02-01
A2: FIN-2026-10-02-01 stated $53.36. The unrounded lines there sum to $53.360098. Rounded lines can print about $53.37 because $16.425 becomes $16.43 and $0.005 becomes $0.01. That penny is rounding, not a missing line. This sheet compares the Live case, at the default inputs, to those unrounded lines. The match expects task public IPv4 off, NAT off, and the four volumes at 1,000 with multipliers at 1.
A4: Line | B4: FIN-2026-10-02-01 exact USD | C4: This model | D4: Delta
A5: Fargate, 1 task, 0.25 vCPU, 0.5 GB | B5: 9.010098 | C5: =Live!B28 | D5: =C5-B5
A6: ALB hours | B6: 16.425 | C6: =Live!B29 | D6: =C6-B6
A7: ALB LCU, 1 LCU | B7: 5.84 | C7: =Live!B30 | D7: =C7-B7
A8: Public IPv4, 2 addresses | B8: 7.3 | C8: =Live!B31 | D8: =C8-B8
A9: RDS db.t4g.micro | B9: 11.68 | C9: =Live!B32 | D9: =C9-B9
A10: gp3 20 GB | B10: 2.3 | C10: =Live!B33 | D10: =C10-B10
A11: Secrets Manager | B11: 0.805 | C11: =Live!B34 | D11: =C11-B11
A12: CloudWatch | B12: 0 | C12: =Live!B35 | D12: =C12-B12
A13: Data transfer | B13: 0 | C13: =Live!B36 | D13: =C13-B13
A14: NAT | B14: 0 | C14: =Live!B37 | D14: =C14-B14
A15: Held at zero | B15: 0 | C15: =Live!B38 | D15: =C15-B15
A16: Exact sum | B16: =SUM(B5:B15) | C16: =Live!B39 | D16: =C16-B16
A17: Rounded to the cent | B17: =ROUND(B16,2) | C17: =Live!B40 | D17: =C17-B17
A19: Floor conditions | B19: =IF(AND(Users=1000,Bots=1000,Offers=1000,Messages=1000,ReqPerUser=1,ReqPerBot=1,ReqPerOffer=1,ReqPerMessage=1,Peak=1,ReqKB=1,RespMult=1,ReqPerConn=1,LogPerM=1,DbFloor=20,DbPerM=0.1,AppVcpuS=0.01,DbVcpuS=0.01,HoldS=1,NatOn=0,TaskPublicIp=0,Live!B12=1,Live!B11=0.25),"Floor matches the FIN-2026-10-02-01 basis","Inputs are not at the floor. The delta is expected.")
A21: Known deltas if you leave the floor
A22: Task public IPv4 on | B22: Adds one in-use address per task at $0.005 per hour. One task is $3.65. Express Mode enables assignPublicIp on the default public subnets. This model leaves that off so the floor matches FIN-2026-10-02-01.
A23: NAT on | B23: Adds 730 x $0.045 = $32.85 plus $0.045 per data-transfer GB. That $32.85 is the FIN-2026-10-02-01 sensitivity and is not in $53.36.
A24: Log GB and storage | B24: At the floor both stay inside the amounts FIN-2026-10-02-01 priced at $0 and $2.30. They rise on the higher rungs because the per-million inputs are not zero.
A25: Data transfer dollars | B25: Priced at $0.01 per GB after 100 GB, the regional rate in the EC2 us-east-1 price list. Internet-egress tier dollars were not in that file, so this can understate traffic to clients. The GB column is still calculated.

Sheet Rates
A1: FIN-2026-10-02-02 rates
A2: us-east-1, 730 hours, on-demand. No Savings Plans. No blended dollar-per-request rate. Every price below has a URL and the date it was read. Yellow cells are the rates the model uses. Do not paste totals over them.
A4: Name | B4: Value | C4: Unit | D4: URL | E4: Date read | F4: What it is
A5: Hours in the model month | B5: 730 | C5: hours | D5: https://aws.amazon.com/fargate/pricing/ | E5: 2026-10-02 | F5: 730 hours is the month length used on the Fargate, RDS, and ELB examples this model reuses from FIN-2026-10-02-01.
A6: Fargate Linux/x86 CPU | B6: 1.1244e-05 | C6: USD per vCPU-second | D6: https://aws.amazon.com/fargate/pricing/ | E6: 2026-10-02 | F6: US East (N. Virginia), Linux/X86, example 1 on the Fargate pricing page. ARM is not used. Option A does not lock Graviton.
A7: Fargate Linux/x86 memory | B7: 1.235e-06 | C7: USD per GB-second | D7: https://aws.amazon.com/fargate/pricing/ | E7: 2026-10-02 | F7: Same example. 0.5 GB is the pricing figure for the 512 MiB minimum, not a claim that the API fits in 0.5 GB.
A8: ALB hourly | B8: 0.0225 | C8: USD per hour | D8: https://aws.amazon.com/elasticloadbalancing/pricing/ | E8: 2026-10-02 | F8: Application Load Balancer, US East (N. Virginia). No separate Express Mode SKU. You pay the load balancer Express stands up.
A9: ALB LCU | B9: 0.008 | C9: USD per LCU-hour | D9: https://aws.amazon.com/elasticloadbalancing/pricing/ | E9: 2026-10-02 | F9: Same page. One LCU covers 25 new connections/second, 3,000 active connections, or 1 GB processed per hour for container targets. The first 10 rule evaluations are free. This model does not blend those into a dollar-per-request rate.
A10: Public IPv4 in-use | B10: 0.005 | C10: USD per address-hour | D10: https://aws.amazon.com/vpc/pricing/ | E10: 2026-10-02 | F10: In-use public IPv4 address, all commercial regions, $0.005 per hour. FIN-2026-10-02-01 counted 2 addresses on the one load balancer.
A11: RDS gp3 storage | B11: 0.115 | C11: USD per GB-month | D11: https://pricing.us-east-1.amazonaws.com/offers/v1.0/aws/AmazonRDS/current/us-east-1/index.csv | E11: 2026-10-02 | F11: Price list published 2026-10-01T06:02:30Z. Description: $0.115 per GB-month of provisioned GP3 storage running PostgreSQL, Single-AZ. No extra provisioned throughput.
A12: Secrets Manager secret | B12: 0.4 | C12: USD per secret-month | D12: https://aws.amazon.com/secrets-manager/pricing/ | E12: 2026-10-02 | F12: Example 1. Two secrets, same as FIN-2026-10-02-01.
A13: Secrets Manager API | B13: 0.05 | C13: USD per 10,000 calls | D13: https://aws.amazon.com/secrets-manager/pricing/ | E13: 2026-10-02 | F13: Same example. The model keeps 1,000 calls at the floor so this line stays $0.005.
A14: CloudWatch Logs ingest | B14: 0.5 | C14: USD per GB | D14: https://aws.amazon.com/cloudwatch/pricing/ | E14: 2026-10-02 | F14: Charged only above the 5 GB free tier. At or under 5 GB the line is $0, which is how FIN-2026-10-02-01 treated 1 GB.
A15: CloudWatch Logs store | B15: 0.03 | C15: USD per GB-month | D15: https://aws.amazon.com/cloudwatch/pricing/ | E15: 2026-10-02 | F15: Archive rate from the same examples. Applied only to GB above the 5 GB free tier. The model assumes the month of logs is retained uncompressed.
A16: CloudWatch free tier | B16: 5 | C16: GB per month | D16: https://aws.amazon.com/cloudwatch/pricing/ | E16: 2026-10-02 | F16: 5 GB ingestion and 5 GB archive. Metrics in this model are the default service metrics only, $0.
... A34: Aurora vCPU per ACU | B34: 1 | C34: vCPU assumed per ACU | D34: https://aws.amazon.com/rds/aurora/pricing/ | E34: 2026-10-02 | F34: Finance assumption, not a published vCPU figure. AWS publishes about 2 GiB per ACU and not a vCPU count. The alternate column counts 1 ACU as 1 vCPU, with a floor of 0.5 ACU.

Sheet Classes
A1: Single-AZ PostgreSQL classes and Fargate sizes
A2: Classes are current generation, On-Demand, regional Single-AZ PostgreSQL (Location Type = AWS Region; Database Engine = PostgreSQL), from the RDS us-east-1 price list published 2026-10-01T06:02:30Z, read 2026-10-02. Outpost / Outposts SKUs are excluded. Sorted by hourly price ascending then class name so the first row that clears CPU and connections is the cheapest. Connection cap uses advertised GiB and the published formula LEAST(bytes/9531392, 5000). Usable vCPU is vCPU times the 60% target. Fargate sizes are the Linux minimum memory for each CPU from the task size table, read 2026-10-02.
A4: Class | B4: USD per hour | C4: vCPU | D4: Memory GiB | E4: Family | F4: Connection cap | G4: Usable vCPU at target | I4: Fargate vCPU | J4: Minimum memory GB
A5: db.t4g.micro | B5: 0.016 | C5: 2 | D5: 1 | E5: General purpose | F5: =MIN(ConnCapMax,D5*1024*1024*1024/ConnDivisor) | G5: =C5*CpuTarget | I5: 0.25 | J5: 0.5
A6: db.t3.micro | B6: 0.018 | C6: 2 | D6: 1 | E6: General purpose | F6: =MIN(ConnCapMax,D6*1024*1024*1024/ConnDivisor) | G6: =C6*CpuTarget | I6: 0.5 | J6: 1
A7: db.t4g.small | B7: 0.032 | C7: 2 | D7: 2 | E7: General purpose | F7: =MIN(ConnCapMax,D7*1024*1024*1024/ConnDivisor) | G7: =C7*CpuTarget | I7: 1 | J7: 2
A8: db.t3.small | B8: 0.036 | C8: 2 | D8: 2 | E8: General purpose | F8: =MIN(ConnCapMax,D8*1024*1024*1024/ConnDivisor) | G8: =C8*CpuTarget | I8: 2 | J8: 4
A9: db.t4g.medium | B9: 0.065 | C9: 2 | D9: 4 | E9: General purpose | F9: =MIN(ConnCapMax,D9*1024*1024*1024/ConnDivisor) | G9: =C9*CpuTarget | I9: 4 | J9: 8
A10: db.t3.medium | B10: 0.072 | C10: 2 | D10: 4 | E10: General purpose | F10: =MIN(ConnCapMax,D10*1024*1024*1024/ConnDivisor) | G10: =C10*CpuTarget | I10: 8 | J10: 16
A11: db.t4g.large | B11: 0.129 | C11: 2 | D11: 8 | E11: General purpose | F11: =MIN(ConnCapMax,D11*1024*1024*1024/ConnDivisor) | G11: =C11*CpuTarget | I11: 16 | J11: 32
A12: db.t3.large | B12: 0.145 | C12: 2 | D12: 8 | E12: General purpose | F12: =MIN(ConnCapMax,D12*1024*1024*1024/ConnDivisor) | G12: =C12*CpuTarget | I12: 32 | J12: 60
A13: db.m6g.large | B13: 0.159 | C13: 2 | D13: 8 | E13: General purpose | F13: =MIN(ConnCapMax,D13*1024*1024*1024/ConnDivisor) | G13: =C13*CpuTarget
A14: db.m7g.large | B14: 0.168 | C14: 2 | D14: 8 | E14: General purpose | F14: =MIN(ConnCapMax,D14*1024*1024*1024/ConnDivisor) | G14: =C14*CpuTarget | I14: Source | J14: https://docs.aws.amazon.com/AmazonECS/latest/developerguide/task_definition_parameters.html
A15: db.m8g.large | B15: 0.168 | C15: 2 | D15: 8 | E15: General purpose | F15: =MIN(ConnCapMax,D15*1024*1024*1024/ConnDivisor) | G15: =C15*CpuTarget | I15: Date read | J15: 2026-10-02
A16: db.m5.large | B16: 0.178 | C16: 2 | D16: 8 | E16: General purpose | F16: =MIN(ConnCapMax,D16*1024*1024*1024/ConnDivisor) | G16: =C16*CpuTarget | I16: Note | J16: 32 vCPU minimum memory is 60 GB on that table (60, 120, or 244 GB). The model uses the minimum.
A17: db.m6i.large | B17: 0.178 | C17: 2 | D17: 8 | E17: General purpose | F17: =MIN(ConnCapMax,D17*1024*1024*1024/ConnDivisor) | G17: =C17*CpuTarget
A18: db.m7i.large | B18: 0.178 | C18: 2 | D18: 8 | E18: General purpose | F18: =MIN(ConnCapMax,D18*1024*1024*1024/ConnDivisor) | G18: =C18*CpuTarget
A19: db.m9g.large | B19: 0.183 | C19: 2 | D19: 8 | E19: General purpose | F19: =MIN(ConnCapMax,D19*1024*1024*1024/ConnDivisor) | G19: =C19*CpuTarget
A20: db.m6gd.large | B20: 0.187 | C20: 2 | D20: 8 | E20: General purpose | F20: =MIN(ConnCapMax,D20*1024*1024*1024/ConnDivisor) | G20: =C20*CpuTarget
A21: db.m8gd.large | B21: 0.1976 | C21: 2 | D21: 8 | E21: Memory optimized | F21: =MIN(ConnCapMax,D21*1024*1024*1024/ConnDivisor) | G21: =C21*CpuTarget
A22: db.m5d.large | B22: 0.21 | C22: 2 | D22: 8 | E22: General purpose | F22: =MIN(ConnCapMax,D22*1024*1024*1024/ConnDivisor) | G22: =C22*CpuTarget
A23: db.m8a.large | B23: 0.2149 | C23: 2 | D23: 8 | E23: General purpose | F23: =MIN(ConnCapMax,D23*1024*1024*1024/ConnDivisor) | G23: =C23*CpuTarget
A24: db.m6id.large | B24: 0.224 | C24: 2 | D24: 8 | E24: General purpose | F24: =MIN(ConnCapMax,D24*1024*1024*1024/ConnDivisor) | G24: =C24*CpuTarget
A25: db.r6g.large | B25: 0.225 | C25: 2 | D25: 16 | E25: Memory optimized | F25: =MIN(ConnCapMax,D25*1024*1024*1024/ConnDivisor) | G25: =C25*CpuTarget
A26: db.r7g.large | B26: 0.239 | C26: 2 | D26: 16 | E26: Memory optimized | F26: =MIN(ConnCapMax,D26*1024*1024*1024/ConnDivisor) | G26: =C26*CpuTarget
A27: db.r8g.large | B27: 0.239 | C27: 2 | D27: 16 | E27: Memory optimized | F27: =MIN(ConnCapMax,D27*1024*1024*1024/ConnDivisor) | G27: =C27*CpuTarget
A28: db.r5.large | B28: 0.25 | C28: 2 | D28: 16 | E28: Memory optimized | F28: =MIN(ConnCapMax,D28*1024*1024*1024/ConnDivisor) | G28: =C28*CpuTarget
... A265: db.x2iedn.32xlarge | B265: 60.864 | C265: 128 | D265: 4096 | E265: Memory optimized | F265: =MIN(ConnCapMax,D265*1024*1024*1024/ConnDivisor) | G265: =C265*CpuTarget
